[2023-10-03T12:27:09.422+0000] {taskinstance.py:1125} INFO - Dependencies all met for dep_context=non-requeueable deps ti=<TaskInstance: launches_getter.create_empty_bigquery_dataset scheduled__2023-09-24T00:00:00+00:00 [queued]>
[2023-10-03T12:27:09.490+0000] {taskinstance.py:1125} INFO - Dependencies all met for dep_context=requeueable deps ti=<TaskInstance: launches_getter.create_empty_bigquery_dataset scheduled__2023-09-24T00:00:00+00:00 [queued]>
[2023-10-03T12:27:09.498+0000] {taskinstance.py:1331} INFO - Starting attempt 1 of 1
[2023-10-03T12:27:09.680+0000] {taskinstance.py:1350} INFO - Executing <Task(BigQueryCreateEmptyTableOperator): create_empty_bigquery_dataset> on 2023-09-24 00:00:00+00:00
[2023-10-03T12:27:09.805+0000] {standard_task_runner.py:57} INFO - Started process 5603 to run task
[2023-10-03T12:27:09.843+0000] {standard_task_runner.py:84} INFO - Running: ['***', 'tasks', 'run', 'launches_getter', 'create_empty_bigquery_dataset', 'scheduled__2023-09-24T00:00:00+00:00', '--job-id', '207', '--raw', '--subdir', 'DAGS_FOLDER/launches.py', '--cfg-path', '/tmp/tmpm16ggr_m']
[2023-10-03T12:27:09.894+0000] {standard_task_runner.py:85} INFO - Job 207: Subtask create_empty_bigquery_dataset
[2023-10-03T12:27:10.761+0000] {task_command.py:410} INFO - Running <TaskInstance: launches_getter.create_empty_bigquery_dataset scheduled__2023-09-24T00:00:00+00:00 [running]> on host f21dc12153d8
[2023-10-03T12:27:12.742+0000] {taskinstance.py:1570} INFO - Exporting env vars: AIRFLOW_CTX_DAG_OWNER='***' AIRFLOW_CTX_DAG_ID='launches_getter' AIRFLOW_CTX_TASK_ID='create_empty_bigquery_dataset' AIRFLOW_CTX_EXECUTION_DATE='2023-09-24T00:00:00+00:00' AIRFLOW_CTX_TRY_NUMBER='1' AIRFLOW_CTX_DAG_RUN_ID='scheduled__2023-09-24T00:00:00+00:00'
[2023-10-03T12:27:12.966+0000] {taskinstance.py:1847} ERROR - Task failed with exception
Traceback (most recent call last):
  File "/home/airflow/.local/lib/python3.7/site-packages/airflow/providers/google/cloud/operators/bigquery.py", line 1350, in execute
    impersonation_chain=self.impersonation_chain,
  File "/home/airflow/.local/lib/python3.7/site-packages/airflow/providers/google/cloud/hooks/bigquery.py", line 107, in __init__
    impersonation_chain=impersonation_chain,
  File "/home/airflow/.local/lib/python3.7/site-packages/airflow/providers/google/common/hooks/base_google.py", line 234, in __init__
    self.extras: dict = self.get_connection(self.gcp_conn_id).extra_dejson
  File "/home/airflow/.local/lib/python3.7/site-packages/airflow/hooks/base.py", line 72, in get_connection
    conn = Connection.get_connection_from_secrets(conn_id)
  File "/home/airflow/.local/lib/python3.7/site-packages/airflow/models/connection.py", line 434, in get_connection_from_secrets
    raise AirflowNotFoundException(f"The conn_id `{conn_id}` isn't defined")
airflow.exceptions.AirflowNotFoundException: The conn_id `google_cloud_default` isn't defined
[2023-10-03T12:27:13.031+0000] {taskinstance.py:1373} INFO - Marking task as FAILED. dag_id=launches_getter, task_id=create_empty_bigquery_dataset, execution_date=20230924T000000, start_date=20231003T122709, end_date=20231003T122713
[2023-10-03T12:27:13.147+0000] {standard_task_runner.py:109} ERROR - Failed to execute job 207 for task create_empty_bigquery_dataset (The conn_id `google_cloud_default` isn't defined; 5603)
[2023-10-03T12:27:13.200+0000] {local_task_job_runner.py:232} INFO - Task exited with return code 1
[2023-10-03T12:27:13.353+0000] {taskinstance.py:2674} INFO - 0 downstream tasks scheduled from follow-on schedule check
[2023-10-03T12:32:01.391+0000] {taskinstance.py:1125} INFO - Dependencies all met for dep_context=non-requeueable deps ti=<TaskInstance: launches_getter.create_empty_bigquery_dataset scheduled__2023-09-24T00:00:00+00:00 [queued]>
[2023-10-03T12:32:01.476+0000] {taskinstance.py:1125} INFO - Dependencies all met for dep_context=requeueable deps ti=<TaskInstance: launches_getter.create_empty_bigquery_dataset scheduled__2023-09-24T00:00:00+00:00 [queued]>
[2023-10-03T12:32:01.477+0000] {taskinstance.py:1331} INFO - Starting attempt 1 of 1
[2023-10-03T12:32:01.605+0000] {taskinstance.py:1350} INFO - Executing <Task(BigQueryCreateEmptyTableOperator): create_empty_bigquery_dataset> on 2023-09-24 00:00:00+00:00
[2023-10-03T12:32:01.647+0000] {standard_task_runner.py:57} INFO - Started process 235 to run task
[2023-10-03T12:32:01.663+0000] {standard_task_runner.py:84} INFO - Running: ['***', 'tasks', 'run', 'launches_getter', 'create_empty_bigquery_dataset', 'scheduled__2023-09-24T00:00:00+00:00', '--job-id', '291', '--raw', '--subdir', 'DAGS_FOLDER/launches.py', '--cfg-path', '/tmp/tmp5bt9el9q']
[2023-10-03T12:32:01.691+0000] {standard_task_runner.py:85} INFO - Job 291: Subtask create_empty_bigquery_dataset
[2023-10-03T12:32:01.882+0000] {task_command.py:410} INFO - Running <TaskInstance: launches_getter.create_empty_bigquery_dataset scheduled__2023-09-24T00:00:00+00:00 [running]> on host f21dc12153d8
[2023-10-03T12:32:02.410+0000] {taskinstance.py:1570} INFO - Exporting env vars: AIRFLOW_CTX_DAG_OWNER='***' AIRFLOW_CTX_DAG_ID='launches_getter' AIRFLOW_CTX_TASK_ID='create_empty_bigquery_dataset' AIRFLOW_CTX_EXECUTION_DATE='2023-09-24T00:00:00+00:00' AIRFLOW_CTX_TRY_NUMBER='1' AIRFLOW_CTX_DAG_RUN_ID='scheduled__2023-09-24T00:00:00+00:00'
[2023-10-03T12:32:02.426+0000] {base.py:73} INFO - Using connection ID 'google_cloud_connection' for task execution.
[2023-10-03T12:32:02.440+0000] {bigquery.py:1365} INFO - Creating table
[2023-10-03T12:32:03.051+0000] {taskinstance.py:1847} ERROR - Task failed with exception
Traceback (most recent call last):
  File "/home/airflow/.local/lib/python3.7/site-packages/airflow/providers/google/cloud/operators/bigquery.py", line 1378, in execute
    exists_ok=self.if_exists == IfExistAction.IGNORE,
  File "/home/airflow/.local/lib/python3.7/site-packages/airflow/providers/google/common/hooks/base_google.py", line 468, in inner_wrapper
    return func(self, *args, **kwargs)
  File "/home/airflow/.local/lib/python3.7/site-packages/airflow/providers/google/cloud/hooks/bigquery.py", line 407, in create_empty_table
    table=table, exists_ok=exists_ok, retry=retry
  File "/home/airflow/.local/lib/python3.7/site-packages/google/cloud/bigquery/client.py", line 755, in create_table
    timeout=timeout,
  File "/home/airflow/.local/lib/python3.7/site-packages/google/cloud/bigquery/client.py", line 782, in _call_api
    return call()
  File "/home/airflow/.local/lib/python3.7/site-packages/google/api_core/retry.py", line 288, in retry_wrapped_func
    on_error=on_error,
  File "/home/airflow/.local/lib/python3.7/site-packages/google/api_core/retry.py", line 190, in retry_target
    return target()
  File "/home/airflow/.local/lib/python3.7/site-packages/google/cloud/_http/__init__.py", line 494, in api_request
    raise exceptions.from_http_response(response)
google.api_core.exceptions.NotFound: 404 POST https://bigquery.googleapis.com/bigquery/v2/projects/aflow-training-rabo-2023-10-02/datasets/ws_dataset/tables?prettyPrint=false: Not found: Dataset aflow-training-rabo-2023-10-02:ws_dataset
[2023-10-03T12:32:03.060+0000] {taskinstance.py:1373} INFO - Marking task as FAILED. dag_id=launches_getter, task_id=create_empty_bigquery_dataset, execution_date=20230924T000000, start_date=20231003T123201, end_date=20231003T123203
[2023-10-03T12:32:03.079+0000] {standard_task_runner.py:109} ERROR - Failed to execute job 291 for task create_empty_bigquery_dataset (404 POST https://bigquery.googleapis.com/bigquery/v2/projects/aflow-training-rabo-2023-10-02/datasets/ws_dataset/tables?prettyPrint=false: Not found: Dataset aflow-training-rabo-2023-10-02:ws_dataset; 235)
[2023-10-03T12:32:03.101+0000] {local_task_job_runner.py:232} INFO - Task exited with return code 1
[2023-10-03T12:32:03.115+0000] {taskinstance.py:2674} INFO - 0 downstream tasks scheduled from follow-on schedule check
