[2023-10-03T09:45:02.422+0000] {taskinstance.py:1125} INFO - Dependencies all met for dep_context=non-requeueable deps ti=<TaskInstance: launches_getter.check_data_in_a_day manual__2023-10-03T09:44:56.808552+00:00 [queued]>
[2023-10-03T09:45:02.441+0000] {taskinstance.py:1125} INFO - Dependencies all met for dep_context=requeueable deps ti=<TaskInstance: launches_getter.check_data_in_a_day manual__2023-10-03T09:44:56.808552+00:00 [queued]>
[2023-10-03T09:45:02.442+0000] {taskinstance.py:1331} INFO - Starting attempt 1 of 1
[2023-10-03T09:45:02.481+0000] {taskinstance.py:1350} INFO - Executing <Task(PythonOperator): check_data_in_a_day> on 2023-10-03 09:44:56.808552+00:00
[2023-10-03T09:45:02.486+0000] {standard_task_runner.py:57} INFO - Started process 2535 to run task
[2023-10-03T09:45:02.488+0000] {standard_task_runner.py:84} INFO - Running: ['***', 'tasks', 'run', 'launches_getter', 'check_data_in_a_day', 'manual__2023-10-03T09:44:56.808552+00:00', '--job-id', '136', '--raw', '--subdir', 'DAGS_FOLDER/launches.py', '--cfg-path', '/tmp/tmpb3surh49']
[2023-10-03T09:45:02.488+0000] {standard_task_runner.py:85} INFO - Job 136: Subtask check_data_in_a_day
[2023-10-03T09:45:02.533+0000] {task_command.py:410} INFO - Running <TaskInstance: launches_getter.check_data_in_a_day manual__2023-10-03T09:44:56.808552+00:00 [running]> on host f21dc12153d8
[2023-10-03T09:45:02.619+0000] {taskinstance.py:1570} INFO - Exporting env vars: AIRFLOW_CTX_DAG_OWNER='***' AIRFLOW_CTX_DAG_ID='launches_getter' AIRFLOW_CTX_TASK_ID='check_data_in_a_day' AIRFLOW_CTX_EXECUTION_DATE='2023-10-03T09:44:56.808552+00:00' AIRFLOW_CTX_TRY_NUMBER='1' AIRFLOW_CTX_DAG_RUN_ID='manual__2023-10-03T09:44:56.808552+00:00'
[2023-10-03T09:45:02.628+0000] {taskinstance.py:1847} ERROR - Task failed with exception
Traceback (most recent call last):
  File "/home/airflow/.local/lib/python3.7/site-packages/airflow/operators/python.py", line 181, in execute
    return_value = self.execute_callable()
  File "/home/airflow/.local/lib/python3.7/site-packages/airflow/operators/python.py", line 198, in execute_callable
    return self.python_callable(*self.op_args, **self.op_kwargs)
  File "/opt/airflow/dags/launches.py", line 47, in _check_if_data_in_request
    raise AirflowSkipException(f"No data found on date {context['ds']}")
NameError: name 'context' is not defined
[2023-10-03T09:45:02.634+0000] {taskinstance.py:1373} INFO - Marking task as FAILED. dag_id=launches_getter, task_id=check_data_in_a_day, execution_date=20231003T094456, start_date=20231003T094502, end_date=20231003T094502
[2023-10-03T09:45:02.650+0000] {standard_task_runner.py:109} ERROR - Failed to execute job 136 for task check_data_in_a_day (name 'context' is not defined; 2535)
[2023-10-03T09:45:02.663+0000] {local_task_job_runner.py:232} INFO - Task exited with return code 1
[2023-10-03T09:45:02.679+0000] {taskinstance.py:2674} INFO - 0 downstream tasks scheduled from follow-on schedule check
