[2023-10-03T10:12:24.368+0000] {taskinstance.py:1125} INFO - Dependencies all met for dep_context=non-requeueable deps ti=<TaskInstance: launches_getter.preprocess_data scheduled__2023-09-27T00:00:00+00:00 [queued]>
[2023-10-03T10:12:24.434+0000] {taskinstance.py:1125} INFO - Dependencies all met for dep_context=requeueable deps ti=<TaskInstance: launches_getter.preprocess_data scheduled__2023-09-27T00:00:00+00:00 [queued]>
[2023-10-03T10:12:24.436+0000] {taskinstance.py:1331} INFO - Starting attempt 2 of 2
[2023-10-03T10:12:24.517+0000] {taskinstance.py:1350} INFO - Executing <Task(PythonOperator): preprocess_data> on 2023-09-27 00:00:00+00:00
[2023-10-03T10:12:24.531+0000] {standard_task_runner.py:57} INFO - Started process 3143 to run task
[2023-10-03T10:12:24.543+0000] {standard_task_runner.py:84} INFO - Running: ['***', 'tasks', 'run', 'launches_getter', 'preprocess_data', 'scheduled__2023-09-27T00:00:00+00:00', '--job-id', '196', '--raw', '--subdir', 'DAGS_FOLDER/launches.py', '--cfg-path', '/tmp/tmp778tl09z']
[2023-10-03T10:12:24.545+0000] {standard_task_runner.py:85} INFO - Job 196: Subtask preprocess_data
[2023-10-03T10:12:24.731+0000] {task_command.py:410} INFO - Running <TaskInstance: launches_getter.preprocess_data scheduled__2023-09-27T00:00:00+00:00 [running]> on host f21dc12153d8
[2023-10-03T10:12:25.132+0000] {taskinstance.py:1570} INFO - Exporting env vars: AIRFLOW_CTX_DAG_OWNER='***' AIRFLOW_CTX_DAG_ID='launches_getter' AIRFLOW_CTX_TASK_ID='preprocess_data' AIRFLOW_CTX_EXECUTION_DATE='2023-09-27T00:00:00+00:00' AIRFLOW_CTX_TRY_NUMBER='2' AIRFLOW_CTX_DAG_RUN_ID='scheduled__2023-09-27T00:00:00+00:00'
[2023-10-03T10:12:26.321+0000] {taskinstance.py:1847} ERROR - Task failed with exception
Traceback (most recent call last):
  File "/home/airflow/.local/lib/python3.7/site-packages/airflow/operators/python.py", line 181, in execute
    return_value = self.execute_callable()
  File "/home/airflow/.local/lib/python3.7/site-packages/airflow/operators/python.py", line 198, in execute_callable
    return self.python_callable(*self.op_args, **self.op_kwargs)
  File "/opt/airflow/dags/launches.py", line 73, in _preprocess_data
    df_results.to_parquet(f"path=/tmp/{context['ds']}.parquet")
  File "/home/airflow/.local/lib/python3.7/site-packages/pandas/util/_decorators.py", line 207, in wrapper
    return func(*args, **kwargs)
  File "/home/airflow/.local/lib/python3.7/site-packages/pandas/core/frame.py", line 2685, in to_parquet
    **kwargs,
  File "/home/airflow/.local/lib/python3.7/site-packages/pandas/io/parquet.py", line 423, in to_parquet
    **kwargs,
  File "/home/airflow/.local/lib/python3.7/site-packages/pandas/io/parquet.py", line 180, in write
    is_dir=partition_cols is not None,
  File "/home/airflow/.local/lib/python3.7/site-packages/pandas/io/parquet.py", line 102, in _get_path_or_handle
    path_or_handle, mode, is_text=False, storage_options=storage_options
  File "/home/airflow/.local/lib/python3.7/site-packages/pandas/io/common.py", line 711, in get_handle
    handle = open(handle, ioargs.mode)
FileNotFoundError: [Errno 2] No such file or directory: 'path=/tmp/2023-09-27.parquet'
[2023-10-03T10:12:26.356+0000] {taskinstance.py:1373} INFO - Marking task as FAILED. dag_id=launches_getter, task_id=preprocess_data, execution_date=20230927T000000, start_date=20231003T101224, end_date=20231003T101226
[2023-10-03T10:12:27.512+0000] {standard_task_runner.py:109} ERROR - Failed to execute job 196 for task preprocess_data ([Errno 2] No such file or directory: 'path=/tmp/2023-09-27.parquet'; 3143)
[2023-10-03T10:12:27.572+0000] {local_task_job_runner.py:232} INFO - Task exited with return code 1
[2023-10-03T10:12:27.613+0000] {taskinstance.py:2674} INFO - 0 downstream tasks scheduled from follow-on schedule check
