[2023-10-03T09:40:30.511+0000] {taskinstance.py:1125} INFO - Dependencies all met for dep_context=non-requeueable deps ti=<TaskInstance: launches_getter.check_data_in_a_day manual__2023-10-03T09:40:26.567631+00:00 [queued]>
[2023-10-03T09:40:30.518+0000] {taskinstance.py:1125} INFO - Dependencies all met for dep_context=requeueable deps ti=<TaskInstance: launches_getter.check_data_in_a_day manual__2023-10-03T09:40:26.567631+00:00 [queued]>
[2023-10-03T09:40:30.519+0000] {taskinstance.py:1331} INFO - Starting attempt 1 of 1
[2023-10-03T09:40:30.539+0000] {taskinstance.py:1350} INFO - Executing <Task(PythonOperator): check_data_in_a_day> on 2023-10-03 09:40:26.567631+00:00
[2023-10-03T09:40:30.544+0000] {standard_task_runner.py:57} INFO - Started process 2432 to run task
[2023-10-03T09:40:30.546+0000] {standard_task_runner.py:84} INFO - Running: ['***', 'tasks', 'run', 'launches_getter', 'check_data_in_a_day', 'manual__2023-10-03T09:40:26.567631+00:00', '--job-id', '127', '--raw', '--subdir', 'DAGS_FOLDER/launches.py', '--cfg-path', '/tmp/tmp7tu_n793']
[2023-10-03T09:40:30.546+0000] {standard_task_runner.py:85} INFO - Job 127: Subtask check_data_in_a_day
[2023-10-03T09:40:30.597+0000] {task_command.py:410} INFO - Running <TaskInstance: launches_getter.check_data_in_a_day manual__2023-10-03T09:40:26.567631+00:00 [running]> on host f21dc12153d8
[2023-10-03T09:40:30.700+0000] {taskinstance.py:1570} INFO - Exporting env vars: AIRFLOW_CTX_DAG_OWNER='***' AIRFLOW_CTX_DAG_ID='launches_getter' AIRFLOW_CTX_TASK_ID='check_data_in_a_day' AIRFLOW_CTX_EXECUTION_DATE='2023-10-03T09:40:26.567631+00:00' AIRFLOW_CTX_TRY_NUMBER='1' AIRFLOW_CTX_DAG_RUN_ID='manual__2023-10-03T09:40:26.567631+00:00'
[2023-10-03T09:40:30.712+0000] {taskinstance.py:1847} ERROR - Task failed with exception
Traceback (most recent call last):
  File "/home/airflow/.local/lib/python3.7/site-packages/airflow/operators/python.py", line 181, in execute
    return_value = self.execute_callable()
  File "/home/airflow/.local/lib/python3.7/site-packages/airflow/operators/python.py", line 198, in execute_callable
    return self.python_callable(*self.op_args, **self.op_kwargs)
  File "/opt/airflow/dags/launches.py", line 42, in _check_if_data_in_request
    response_dict = response.loads(response)
AttributeError: 'str' object has no attribute 'loads'
[2023-10-03T09:40:30.735+0000] {taskinstance.py:1373} INFO - Marking task as FAILED. dag_id=launches_getter, task_id=check_data_in_a_day, execution_date=20231003T094026, start_date=20231003T094030, end_date=20231003T094030
[2023-10-03T09:40:30.751+0000] {standard_task_runner.py:109} ERROR - Failed to execute job 127 for task check_data_in_a_day ('str' object has no attribute 'loads'; 2432)
[2023-10-03T09:40:30.817+0000] {local_task_job_runner.py:232} INFO - Task exited with return code 1
[2023-10-03T09:40:30.838+0000] {taskinstance.py:2674} INFO - 0 downstream tasks scheduled from follow-on schedule check
