[2023-10-03T12:30:19.580+0000] {taskinstance.py:1119} INFO - Dependencies not met for <TaskInstance: launches_getter.create_empty_bigquery_dataset scheduled__2023-09-27T00:00:00+00:00 [failed]>, dependency 'Task Instance State' FAILED: Task is in the 'failed' state.
[2023-10-03T12:30:19.599+0000] {local_task_job_runner.py:161} INFO - Task is not able to be run
[2023-10-03T12:32:00.745+0000] {taskinstance.py:1125} INFO - Dependencies all met for dep_context=non-requeueable deps ti=<TaskInstance: launches_getter.create_empty_bigquery_dataset scheduled__2023-09-27T00:00:00+00:00 [queued]>
[2023-10-03T12:32:00.832+0000] {taskinstance.py:1125} INFO - Dependencies all met for dep_context=requeueable deps ti=<TaskInstance: launches_getter.create_empty_bigquery_dataset scheduled__2023-09-27T00:00:00+00:00 [queued]>
[2023-10-03T12:32:00.832+0000] {taskinstance.py:1331} INFO - Starting attempt 1 of 1
[2023-10-03T12:32:00.947+0000] {taskinstance.py:1350} INFO - Executing <Task(BigQueryCreateEmptyTableOperator): create_empty_bigquery_dataset> on 2023-09-27 00:00:00+00:00
[2023-10-03T12:32:00.987+0000] {standard_task_runner.py:57} INFO - Started process 231 to run task
[2023-10-03T12:32:01.002+0000] {standard_task_runner.py:84} INFO - Running: ['***', 'tasks', 'run', 'launches_getter', 'create_empty_bigquery_dataset', 'scheduled__2023-09-27T00:00:00+00:00', '--job-id', '287', '--raw', '--subdir', 'DAGS_FOLDER/launches.py', '--cfg-path', '/tmp/tmpc7330mxx']
[2023-10-03T12:32:01.012+0000] {standard_task_runner.py:85} INFO - Job 287: Subtask create_empty_bigquery_dataset
[2023-10-03T12:32:01.209+0000] {task_command.py:410} INFO - Running <TaskInstance: launches_getter.create_empty_bigquery_dataset scheduled__2023-09-27T00:00:00+00:00 [running]> on host f21dc12153d8
[2023-10-03T12:32:01.778+0000] {taskinstance.py:1570} INFO - Exporting env vars: AIRFLOW_CTX_DAG_OWNER='***' AIRFLOW_CTX_DAG_ID='launches_getter' AIRFLOW_CTX_TASK_ID='create_empty_bigquery_dataset' AIRFLOW_CTX_EXECUTION_DATE='2023-09-27T00:00:00+00:00' AIRFLOW_CTX_TRY_NUMBER='1' AIRFLOW_CTX_DAG_RUN_ID='scheduled__2023-09-27T00:00:00+00:00'
[2023-10-03T12:32:01.828+0000] {base.py:73} INFO - Using connection ID 'google_cloud_connection' for task execution.
[2023-10-03T12:32:01.864+0000] {bigquery.py:1365} INFO - Creating table
[2023-10-03T12:32:02.746+0000] {taskinstance.py:1847} ERROR - Task failed with exception
Traceback (most recent call last):
  File "/home/airflow/.local/lib/python3.7/site-packages/airflow/providers/google/cloud/operators/bigquery.py", line 1378, in execute
    exists_ok=self.if_exists == IfExistAction.IGNORE,
  File "/home/airflow/.local/lib/python3.7/site-packages/airflow/providers/google/common/hooks/base_google.py", line 468, in inner_wrapper
    return func(self, *args, **kwargs)
  File "/home/airflow/.local/lib/python3.7/site-packages/airflow/providers/google/cloud/hooks/bigquery.py", line 407, in create_empty_table
    table=table, exists_ok=exists_ok, retry=retry
  File "/home/airflow/.local/lib/python3.7/site-packages/google/cloud/bigquery/client.py", line 755, in create_table
    timeout=timeout,
  File "/home/airflow/.local/lib/python3.7/site-packages/google/cloud/bigquery/client.py", line 782, in _call_api
    return call()
  File "/home/airflow/.local/lib/python3.7/site-packages/google/api_core/retry.py", line 288, in retry_wrapped_func
    on_error=on_error,
  File "/home/airflow/.local/lib/python3.7/site-packages/google/api_core/retry.py", line 190, in retry_target
    return target()
  File "/home/airflow/.local/lib/python3.7/site-packages/google/cloud/_http/__init__.py", line 494, in api_request
    raise exceptions.from_http_response(response)
google.api_core.exceptions.NotFound: 404 POST https://bigquery.googleapis.com/bigquery/v2/projects/aflow-training-rabo-2023-10-02/datasets/ws_dataset/tables?prettyPrint=false: Not found: Dataset aflow-training-rabo-2023-10-02:ws_dataset
[2023-10-03T12:32:02.813+0000] {taskinstance.py:1373} INFO - Marking task as FAILED. dag_id=launches_getter, task_id=create_empty_bigquery_dataset, execution_date=20230927T000000, start_date=20231003T123200, end_date=20231003T123202
[2023-10-03T12:32:02.840+0000] {standard_task_runner.py:109} ERROR - Failed to execute job 287 for task create_empty_bigquery_dataset (404 POST https://bigquery.googleapis.com/bigquery/v2/projects/aflow-training-rabo-2023-10-02/datasets/ws_dataset/tables?prettyPrint=false: Not found: Dataset aflow-training-rabo-2023-10-02:ws_dataset; 231)
[2023-10-03T12:32:02.866+0000] {local_task_job_runner.py:232} INFO - Task exited with return code 1
[2023-10-03T12:32:02.895+0000] {taskinstance.py:2674} INFO - 0 downstream tasks scheduled from follow-on schedule check
